            int[] nums = new int[4];
            try
            {
                nums[5] = 10; 
                //вылетит ошибка IndexOutOfRange , без обработчика исключений try catch
                int x = 0;
                int y = 9 / x;
                Console.WriteLine("End of try block");
            }       
            catch (DivideByZeroException ex) 
            //объект исключения можно передовать в блок catch в скобках
            //общий тип исключений Exception ex
            {
                Console.WriteLine($"Error occured divided{ ex.Message}"); 
            //в консоль выведится , вместо ошибки IndexOutOfRange
            //ex.Message - даст сообщение Индекс находится вне границ массива
            }
            catch (IndexOutOfRangeException ex) 
            //объект исключения можно передовать в блок catch в скобках
            {
                Console.WriteLine($"Error occured mas { ex.Message}"); 
            //в консоль выведится , вместо ошибки IndexOutOfRange
            //ex.Message - даст сообщение Индекс находится вне границ массива
            }
            catch (Exception ex) 
            //объект исключения можно передовать в блок catch в скобках
            //общий тип исключений Exception ex входят все исключения
            {
                Console.WriteLine($"Error occured { ex.Message}");
            //в консоль выведится , вместо ошибки IndexOutOfRange
            //ex.Message - даст сообщение Индекс находится вне границ массива
            }
            finally   
            //всегда выполняется блок finally 
            {
                Console.WriteLine("finally block");
            }